Workbook

Sheet Mục lục
A1: TỔNG HỢP GIFTCODE — MỤC LỤC
A3: Ngày tổng hợp | B3: 19/10/2026 — từ danh sách 340 link Facebook bạn gửi (file DANH_SACH_LINK_FB_QUET_CODE.md).
A4: Sheet 'Tổng hợp 340 game' | B4: 1 dòng / 1 game: link Facebook, số code tìm được, trạng thái, cách nhập, ghi chú và nguồn. Lọc cột 'Trạng thái' = 'Có code' để xem nhanh 164 game có code.
A5: Sheet 'Tất cả code' | B5: Toàn bộ 1.888 giftcode, mỗi dòng 1 mã. Cột 'Đã nhập?' màu vàng để bạn gõ 'x' đánh dấu; cuối bảng tự đếm đã nhập / chưa nhập.
A6: Sheet 'Ta Là Hắc Ngộ Không' | B6: 35 code của game Ta Là Hắc Ngộ Không (VPlay) — phần làm trước đó, giữ nguyên.
A7: Sheet 'Pirate Legends' | B7: 8 code của Pirate Legends: Huyền Thoại Hải Tặc (Neotrix) — phần làm trước đó, giữ nguyên.
A8: Tổng số game đã quét | B8: ='Tổng hợp 340 game'!C345 -> 340
A9: Số game có code | B9: ='Tổng hợp 340 game'!C346 -> 164
A10: Số game không tìm thấy code | B10: ='Tổng hợp 340 game'!C347 -> 176
A11: Tổng số giftcode (340 game) | B11: ='Tổng hợp 340 game'!C348 -> 1888
A12: Lưu ý trung thực | B12: Facebook không cho liệt kê toàn bộ bài viết của fanpage mà bạn không quản lý, nên code được tổng hợp từ các trang công khai chuyên tổng hợp giftcode (AFKMobi, Taimienphi, CellphoneS... và các nguồn quốc tế) đối chiếu theo từng game/NPH trong danh sách. 'Có code' nghĩa là tìm thấy mã được công bố công khai — hạn dùng chưa được kiểm chứng trực tiếp trong game, nhiều mã có thể đã hết hạn, nên hãy nhập sớm và thử; mã nào game báo hết hạn thì bỏ qua.
A13: Game không tìm thấy code | B13: 176 game không có mã dùng chung công khai ở thời điểm quét (nhiều game chỉ phát code riêng qua sự kiện trong game/fanpage, hoặc không có hệ thống giftcode). Chi tiết lý do nằm ở cột 'Ghi chú kết quả quét' của từng game.

Sheet Ta Là Hắc Ngộ Không
A1: TA LÀ HẮC NGỘ KHÔNG — DANH SÁCH GIFTCODE
A2: Nhà phát hành: VPlay — ra mắt chính thức 10h ngày 14/10/2026
A3: Fanpage: facebook.com/talahacngokhong
A4: Cách nhập: Nhân vật đạt cấp 51 → nút Sảnh Phúc Lợi (góc trên bên trái) → Đổi → nhập code → Nhận Thưởng. Quà gửi về thư trong game. Cũng nhập được tại giftcode.vplay.vn bằng VPlay ID/Facebook/Google.
A5: Tổng hợp từ các kênh chính thức của NPH, được cộng đồng kiểm tra còn dùng được tính đến 18/10/2026. Code phân biệt chữ hoa/thường — copy đúng như trong bảng. Mỗi code chỉ dùng 1 lần/tài khoản.
A6: Ô màu vàng ở cột 'Đã nhập?' là ô bạn tự điền: gõ 'x' khi đã nhập code đó. Tổng kết ở cuối bảng sẽ tự đếm.
A7: STT | B7: Giftcode | C7: Ghi chú / Phần thưởng | D7: Trạng thái | E7: Đã nhập?
A8: 1 | B8: SANSANGDAINAO | D8: Còn dùng được (đến 18/10/2026)
A9: 2 | B9: 1KCHIENHUU | D9: Còn dùng được (đến 18/10/2026)
A10: 3 | B10: TAYTHIENHACHOA | D10: Còn dùng được (đến 18/10/2026)
A11: 4 | B11: 500THANHVIENHNK | D11: Còn dùng được (đến 18/10/2026)
A12: 5 | B12: TALAHACNKGROUP | D12: Còn dùng được (đến 18/10/2026)
A13: 6 | B13: TOP1BXH | D13: Còn dùng được (đến 18/10/2026)
A14: 7 | B14: TLHKH5 | D14: Còn dùng được (đến 18/10/2026)
A15: 8 | B15: THAMTAY666 | D15: Còn dùng được (đến 18/10/2026)
A16: 9 | B16: THAIVG999 | D16: Còn dùng được (đến 18/10/2026)
A17: 10 | B17: DUYNHAT888 | D17: Còn dùng được (đến 18/10/2026)
A18: 11 | B18: XINCHAOTHIENMENH | D18: Còn dùng được (đến 18/10/2026)
A19: 12 | B19: DAINAO | D19: Còn dùng được (đến 18/10/2026)
... A42: 35 | B42: LONGCUNG666 | D42: Còn dùng được (đến 18/10/2026)
B44: Tổng số code: | C44: =COUNTA(B8:B42) -> 35
B45: Đã nhập: | C45: =COUNTIF(E8:E42,"x")+COUNTIF(E8:E42,"X") -> 0
B46: Chưa nhập: | C46: =C44-C45 -> 35

Sheet Pirate Legends
A1: PIRATE LEGENDS: HUYỀN THOẠI HẢI TẶC — DANH SÁCH GIFTCODE
A2: Nhà phát hành: Neotrix — ra mắt chính thức 10h ngày 02/10/2026
A3: Fanpage: facebook.com/piratelegends
A4: Cách nhập: Mở game → nút Phúc Lợi ở phía bên phải màn hình → Giftcode → nhập code → Xác nhận. Quà tự động vào túi trang bị.
A5: 5 code đầu là code ra mắt chính thức từ NPH. 3 code cuối là code nên thử thêm (xem ghi chú) — nếu game báo không hợp lệ thì bỏ qua.
A6: Ô màu vàng ở cột 'Đã nhập?' là ô bạn tự điền: gõ 'x' khi đã nhập code đó. Tổng kết ở cuối bảng sẽ tự đếm.
A7: STT | B7: Giftcode | C7: Ghi chú / Phần thưởng | D7: Trạng thái | E7: Đã nhập?
A8: 1 | B8: ONEPIECEMMO | C8: Code ra mắt chính thức | D8: Code ra mắt
A9: 2 | B9: ONEPIECE2026 | C9: Code ra mắt chính thức | D9: Code ra mắt
A10: 3 | B10: ONEPIECE888 | C10: Code ra mắt chính thức | D10: Code ra mắt
A11: 4 | B11: ONEPIECE666 | C11: Code ra mắt chính thức | D11: Code ra mắt
A12: 5 | B12: HUYENTHOAIHAITAC | C12: Code ra mắt chính thức | D12: Code ra mắt
A13: 6 | B13: Q3SV4U8J6GN1D | C13: Quà ghi nhận: 5 triệu Beli, 10 triệu EXP, 500 Kim Cương, 5 Thùng Bia, 5.000 Đá Cường Hóa. Lưu ý: mã này thấy trong bài về game Huyền Thoại Hải Tặc của NPH GOSU (game khác, tên gần giống) — thử nhập, không hợp lệ thì bỏ qua | D13: Thử nhập — còn hạn đến 16/10/2026*
A14: 7 | B14: ONEPIECE | C14: Code thử thêm — có thể thuộc game Huyền Thoại Hải Tặc của GOSU, không phải Pirate Legends của Neotrix | D14: Thử nhập*
A15: 8 | B15: HTHTVIP | C15: Code thử thêm — có thể thuộc game Huyền Thoại Hải Tặc của GOSU, không phải Pirate Legends của Neotrix | D15: Thử nhập*
B17: Tổng số code: | C17: =COUNTA(B8:B15) -> 8
B18: Đã nhập: | C18: =COUNTIF(E8:E15,"x")+COUNTIF(E8:E15,"X") -> 0
B19: Chưa nhập: | C19: =C17-C18 -> 8

Sheet Tổng hợp 340 game
A1: TỔNG HỢP 340 GAME — KẾT QUẢ QUÉT GIFTCODE (19/10/2026)
A2: Mỗi dòng là 1 mục trong danh sách 340 link Facebook bạn gửi. Cột 'Số code' tự đếm từ sheet 'Tất cả code'. Dùng bộ lọc ở hàng tiêu đề để lọc riêng các game 'Có code' hoặc theo Nhà phát hành.
A3: STT | B3: Tên game | C3: Nhà phát hành | D3: Link Facebook (nguồn quét) | E3: Số code | F3: Trạng thái | G3: Cách nhập code | H3: Ghi chú kết quả quét | I3: Nguồn tham khảo
A4: 1 | B4: 3Q Đào Đào Đào | C4: CÔNG TY TNHH JOYGAMES | D4: https://www.facebook.com/3qdaodaodao | E4: =COUNTA('Tất cả code'!$C$4:$C$11) -> 8 | F4: Có code | G4: Trong game, bấm vào Avatar ở góc trên bên trái màn hình, mở nút Mã quà ở góc dưới bên phải, nhập mã rồi bấm Xác nhận; quà sẽ được gửi về Thư trong game nếu nhập đúng. | H4: Nguồn cập nhật ngày 23/09/2026; code độc quyền của AFKMobi đã phát hết, các code dùng chung còn lại không rõ hạn — nên nhập sớm | I4: https://afkmobi.com/tong-hop-gift-code-game-3q-dao-dao-dao-joygames-moi-nhat.html
A5: 2 | B5: 3Q Gọi Tướng Đi | C5: CÔNG TY CỔ PHẦN GIẢI TRÍ 568E | D5: https://www.facebook.com/3qgoituongdi | E5: =0 -> 0 | F5: Không tìm thấy code | G5: Chưa tìm được hướng dẫn nhập code cụ thể cho game này; theo trang hồ sơ game, code được phát qua các kênh/sự kiện của NPH 568Play | H5: Không tìm thấy code | I5: https://afkmobi.com/game/3q-goi-tuong-di
A6: 3 | B6: Amanotes (Studio Quốc tế) | C6: NPH Chính thức | D6: https://www.facebook.com/magictiles3 | E6: =0 -> 0 | F6: Không tìm thấy code | G6: Không áp dụng | H6: Không tìm thấy code - Các game của Amanotes (Magic Tiles 3, Tiles Hop...) không có hệ thống giftcode chính thức; các trang tổng hợp uy tín không đăng code nào. Các trang linegames.org/aayyy.com trả về danh sách mã ngẫu nhiên dạng spam affiliate, không đáng tin nên không liệt kê.
A7: 4 | B7: Anh Hùng Xạ Điêu - Gamota | C7: Gamota | D7: https://www.facebook.com/ahxd.gamota | E7: =0 -> 0 | F7: Không tìm thấy code | G7: Hoàn thành hướng dẫn tân thủ (đạt level 4), nhấn biểu tượng Settings màu xanh ở góc phải màn hình, nhập giftcode vào ô Gifcode trong bảng Settings (quà sẽ vào hòm đồ) | H7: Không tìm thấy code chung còn hiệu lực. Các nguồn (bài viết từ 2017, game ra mắt 2018) chỉ mô tả cách nhận VIP code riêng qua đăng ký thông tin trên trang chủ (code gửi qua email) hoặc lấy code tại fanpage/trang chủ, không công bố mã code dùng chung cụ thể nào | I7: https://thuthuat.taimienphi.vn/code-anh-hung-xa-dieu-29975n.aspx?ampok=1 https://thuthuat.taimienphi.vn/code-anh-hung-xa-dieu-24722n.aspx
A8: 5 | B8: Ảo Mộng Tru Tiên | C8: Công ty Cổ phần Gamota (Thuộc Appota Group) | D8: https://www.facebook.com/aomongtrutien.gamota | E8: =0 -> 0 | F8: Không tìm thấy code | G8: Chưa xác minh được cách nhập code cụ thể cho game này từ các nguồn uy tín | H8: Không tìm thấy code. Đã quét các trang tổng hợp tiếng Việt — tất cả kết quả đều thuộc các game khác (Mộng Ảo Tu Tiên, Tru Tiên Kiếm Vũ, Tiên Nghịch Mobile...), không có nguồn uy tín nào liệt kê giftcode cho Ảo Mộng Tru Tiên - Gamota. Trang linegames.org có liệt kê một số mã nhưng trông như mã ngẫu nhiên do máy tạo, không đáng tin, nên không đưa vào. | I8: https://aomongtrutien.gamota.com/ https://gamota.com/vi/gamota-lab/tag/jade-dynasty/feed/
A9: 6 | B9: Au 2! | C9: VTC (VTC Intecom & VTC Mobile) | D9: https://www.facebook.com/au2.vtcgame.vn | E9: =COUNTA('Tất cả code'!$C$12:$C$26) -> 15 | F9: Có code | G9: Nhập code trực tiếp trong game trên điện thoại; nên copy code thay vì gõ tay để tránh sai ký tự, nhập sớm vì code thường chỉ có hạn 1-2 tuần, quà sẽ gửi vào hòm thư trong game. | H9: Chưa xác minh. Nguồn duy nhất liệt kê code là bài mytour.vn năm 2023 (cập nhật 11-06-2024); không tìm thấy nguồn nào cập nhật code Au 2 cho 2026, khả năng cao các code trên đã hết hạn. | I9: https://mytour.vn/en/blog/bai-viet/discover-the-latest-2023-updates-for-au-2-audition-mobile-codes-and-how-to-redeem-them https://cellphones.com.vn/sforum/tag/code-game
A10: 7 | B10: Audition - Nhịp Điệu Cuộc Sống | C10: VTC (VTC Intecom & VTC Mobile) | D10: https://www.facebook.com/auditionvtc | E10: =0 -> 0 | F10: Không tìm thấy code | G10: Đăng nhập game Audition (PC) bằng tài khoản VTC ID, nhập mã vào mục giftcode trong game để nhận thưởng (cách nhập lịch sử của VTC cho bản PC). | H10: Không tìm thấy code: bản PC Audition của VTC hiện không có mã giftcode chung công khai trên các trang tổng hợp uy tín. VTC phát giftcode theo sự kiện chứ không công bố danh sách mã chung. | I10: https://vtcpay.vn/tin-tuc-473/tin-tu-vtc-pay-28/1000-khach-hang-nhanh-nhat-da-nhan-duoc-50000d-tu-vtcpay-45307
A11: 8 | B11: Avatar Bum | C11: Công ty TNHH TeaMobi | D11: https://www.facebook.com/avatar.bum.teamobi | E11: =0 -> 0 | F11: Không tìm thấy code | G11: Không xác định được do không có nguồn nào cung cấp danh sách code cụ thể cho game này | H11: Không tìm thấy code | I11: https://thuthuat.taimienphi.vn/canews_code-game-126/Trang/10.aspx https://tusach.vn/download/avatar-bum-3wcy
A12: 9 | B12: Avatar Land | C12: Công ty TNHH TeaMobi | D12: https://www.facebook.com/al.teamobi1 | E12: =0 -> 0 | F12: Không tìm thấy code | G12: Mở game, bấm vào biểu tượng AVATAR (hoặc vào Hồ sơ/Cài đặt), chọn mục Giftcode/Đổi Code, nhập giftcode vào ô trống rồi bấm Xác nhận; phần thưởng sẽ được gửi vào Hòm thư trong game. | H12: Không tìm thấy code — các trang tổng hợp uy tín không có bài code cho game này; nguồn duy nhất liệt kê code đều không đáng tin nên không liệt kê. | I12: https://www.linegames.org/en/avatar-land-codes/ https://www.thegioigameviet.com/search?updated-max=2025-04-06T20:56:00%2B07:00&max-results=20&reverse-paginate=true&start=157&by-date=false
A13: 10 | B13: BangBang Online | C13: Công ty Cổ phần Trực tuyến CMN Việt Nam | D13: https://www.facebook.com/pvtk2.vn | E13: =COUNTA('Tất cả code'!$C$27:$C$33) -> 7 | F13: Có code | G13: Đăng nhập game BangBang Origin > góc phải trên màn hình, dưới thanh menu chọn 'Đổi thưởng HĐ' > chọn 'Nhận Quà' > nhập code và ấn OK | H13: Chưa xác minh. Các mã do thethao247.vn liệt kê trong bài viết từ năm 2023 (game BangBang Origin do CMN Online phát hành); không có thông tin hạn dùng và khả năng cao đã hết hạn | I13: https://thethao247.vn/400-code-bangbang-origin-moi-nhat-va-cach-nhap-d277532.html https://hoanghamobile.com/tin-tuc/bang-bang
A14: 11 | B14: Beat Jumper - EDM Rush up! | C14: Amanotes Pte. Ltd. / Amanotes Vietnam | D14: https://www.facebook.com/magictiles3 | E14: =COUNTA('Tất cả code'!$C$34:$C$45) -> 12 | F14: Có code | G14: Trong game, vào Avatar/Hồ sơ (Profile)/Cài đặt → chọn Redeem Code → nhập code để đổi quà (gói thưởng). | H14: Chưa xác minh. Code lấy từ trang linegames.org (bên thứ ba, không liên kết chính thức với Amanotes/NPH). Dạng flash redeem code, ai nhanh tay đổi trước, đổi 1 lần/1 server, hạn dùng không rõ. | I14: https://www.linegames.org/en/Beat-Jumper-codes/280960208384/?page=1
A15: 12 | B15: Bida ZingPlay | C15: Công ty TNHH ZingPlay Việt Nam (Thuộc VNG) | D15: https://www.facebook.com/zingplayconggame | E15: =0 -> 0 | F15: Không tìm thấy code | G15: Mở app Bida ZingPlay, vào giao diện chính chọn mục Giftcode hoặc Nhập mã quà tặng (có thể trong Cài đặt/Hồ sơ), nhập mã vào ô trống và nhấn Nhập mã/Xác nhận; mỗi code chỉ dùng được một lần cho mỗi tài khoản. | H15: Không tìm thấy code | I15: https://xaydungso.vn/blog5/zingplay-bida-8-vi-cb.html https://xaydungso.vn/blog5/tool-bida-zingplay-android-vi-cb.html
A16: 13 | B16: Blade Ball | C16: Nhà Phát Hành Quốc Tế | D16: https://www.facebook.com/bladeballofficial | E16: =COUNTA('Tất cả code'!$C$46:$C$68) -> 23 | F16: Có code | G16: Mở Roblox và vào game Blade Ball, nhấn nút EXTRA ở phía trên màn hình, chọn CODES, nhập code vào ô trống rồi nhấn nút dấu tick để nhận thưởng. | H16: còn hạn - 2 nguồn uy tín cập nhật tháng 10/2026 (Twinfinite ngày 12/10/2026, Destructoid) đều liệt kê các code này là còn hoạt động; code có thể hết hạn bất cứ lúc nào nên nhập sớm | I16: https://twinfinite.net/roblox/blade-ball-codes/ https://www.destructoid.com/blade-ball-codes-october-2023/
A17: 14 | B17: Bravestars Games | C17: NPH Chính thức | D17: https://www.facebook.com/fptiscareer/posts/122284364222161077 | E17: =0 -> 0 | F17: Không tìm thấy code | H17: Không tìm thấy code. Đã tìm qua 4 truy vấn (vi/en) về Bravestars Games, Hair Salon, Merge Defense, Stickman Revenge; các kết quả chỉ trả về code của game Brawl Stars, các game Roblox tên tương tự hoặc trang spam/affiliate không liên quan - không nguồn nào liệt kê giftcode thực cho game của Bravestars Games.
A18: 15 | B18: Capybara Go! | C18: CÔNG TY CỔ PHẦN BLISS | D18: https://www.facebook.com/capybaragoglobal | E18: =COUNTA('Tất cả code'!$C$69:$C$81) -> 13 | F18: Có code | G18: Chạm vào avatar người chơi góc trái màn hình game để xem và sao chép UID, sau đó truy cập trang gift.capybarago.io, nhập UID và code (phân biệt chữ hoa/thường), nhấn đổi. Nếu thành công, nhận thưởng trong hộp Thư (Mail) trong game. | H18: Danh sách đồng nhất trên nhiều nguồn, được PocketGamer kiểm tra lại ngày 18/10/2026. Lưu ý 'lucky2025' và 'lucky2024' cũng xuất hiện trong mục hết hạn của trang nguồn (mâu thuẫn nội bộ), nên hai code này có thể đã hoặc sắp hết hạn - nên nhập sớm. | I18: http://www.pocketgamer.com/capybara-go/codes/ https://axeetech.com/capybara-go-codes/ https://24hstore.vn/huong-dan-ky-thuat/code-capybara-go-n9888
A19: 16 | B19: Car Race 3D | C19: Công ty Cổ phần iKame (Zego Studio / Begamob) | D19: https://www.facebook.com/mirchifunfb | E19: =0 -> 0 | F19: Không tìm thấy code | G19: Chưa xác minh được cách nhập; game là tựa hyper-casual đua xe của iKame/Zego Studio, không tìm thấy nguồn chính thức hay trang tổng hợp uy tín nào mô tả chức năng nhập giftcode trong game. | H19: Không tìm thấy code. Các trang linegames.org chỉ liệt kê mã ký tự ngẫu nhiên theo mẫu spam affiliate và ghi rõ không liên kết với game, nên không ghi nhận làm code hợp lệ.
A20: 17 | B20: Câu Cá Vạn Cân | C20: CÔNG TY TNHH THẾ GIỚI MINI | D20: https://www.facebook.com/caucavancan.1 | E20: =0 -> 0 | F20: Không tìm thấy code | G20: Chưa có nguồn xác minh nào ghi rõ cách nhập code trong game bản mobile của Thế Giới Mini | H20: Không tìm thấy code. Game mobile của MINI WORLD COMPANY LIMITED mới ra mắt tại VN khoảng tháng 9/2026; trang afkmobi.com có mục tổng hợp code nhưng chưa liệt kê mã nào. Lưu ý: trang gameorb.io liệt kê nhiều mã nhưng thuộc về game Roblox Fish It, không phải game mobile của Thế Giới Mini, nên không liệt kê. | I20: https://afkmobi.com/game/cau-ca-van-can https://gameorb.io/code-cau-ca-van-can/
A21: 18 | B21: Chỉ Huy Tối Thượng | C21: CÔNG TY CỔ PHẦN GAMOTA | D21: https://www.facebook.com/nph.gamota | E21: =COUNTA('Tất cả code'!$C$82:$C$83) -> 2 | F21: Có code | G21: Trong game bấm vào Avatar ở góc trên bên trái màn hình, mở nút "Đổi" phía dưới, nhập mã rồi bấm "Đổi", quà sẽ được nhận ngay lập tức nếu nhập đúng. | H21: không rõ hạn — code dùng chung từ đợt ra mắt game (23/06/2026), bài viết afkmobi cập nhật lần cuối 26/06/2026, không có thông tin code mới sau thời điểm đó; code VIP độc quyền của AFKMobi đã phát hết. | I21: https://afkmobi.com/tong-hop-gift-code-game-chi-huy-toi-thuong-moi-nhat.html https://download.com.vn/s/game+arcade?sort=dateadded&p=270
A22: 19 | B22: Chiến Giới 4D | C22: CÔNG TY CỔ PHẦN TRUYỀN HÌNH TƯƠNG TÁC VIỆT NAM | D22: https://www.facebook.com/chiengioi4d.vplay.vn | E22: =COUNTA('Tất cả code'!$C$84:$C$169) -> 86 | F22: Có code | G22: Vào game → Sảnh phúc lợi → chọn mục Đổi → nhập code → Nhận thưởng → quay lại màn hình chính, mở Thư → Nhận nhanh. Yêu cầu: hoàn thành nhiệm vụ tân thủ và nhân vật đạt cấp 30. | H22: Không rõ hạn. Nguồn (FPT Shop, cập nhật 2026-10-01) đánh dấu 6 code 'Còn hạn' (ChienGioi4D, ChienGioiVip, ChienGioi999, THOITRANGVIP999, CANHVIP999, LANDING999); các code còn lại được gắn 'Mới' nhưng hạn thực tế không rõ — một số code sự kiện theo ngày/tháng cũ rất có thể đã hết hạn. Nên ưu tiên nhập sớm. Một số code có dấu tiếng Việt, cần nhập chính xác từng ký tự. | I22: https://fptshop.com.vn/tin-tuc/giai-tri/cap-nhat-tong-hop-cac-ma-code-chien-gioi-4d-moi-nhat-bat-mi-cach-nhap-code-chinh-xac-va-nhanh-chong-172025 https://Quantrimang.com/cong-nghe/code-chien-gioi-4d-mobile-moi-nhat-190032
A23: 20 | B23: Chiến Thú Hỗn Chiến | C23: CÔNG TY CỔ PHẦN GAMOTA | D23: https://www.facebook.com/nph.gamota | E23: =COUNTA('Tất cả code'!$C$170:$C$174) -> 5 | F23: Có code | G23: Trong game: chạm Avatar ở màn hình chính → Cài đặt → Mã đổi quà → nhập mã → bấm Nhận; quà sẽ gửi về Thư ingame. Code phân biệt chữ hoa/thường, mỗi mã dùng 1 lần mỗi tài khoản. | H23: còn hạn (cập nhật 19/10/2026, 72% bình chọn cộng đồng xác nhận còn dùng được) | I23: https://codemoi.net/games/chien-thu-hon-chien/ https://afkmobi.com/tong-hop-gift-code-game-chien-thu-hon-chien-moi-nhat-trong-thang.html
A24: 21 | B24: Chiến Vì Vinh Quang | C24: CÔNG TY CỔ PHẦN CÔNG NGHỆ SỐ ALO | D24: https://www.facebook.com/oeg.vn | E24: =COUNTA('Tất cả code'!$C$175:$C$177) -> 3 | F24: Có code | G24: Trong game bấm vào Avatar ở góc trên bên trái màn hình, mở nút Giftcode, nhập mã rồi bấm Đổi; quà gửi về Thư trong game (vào Thành Chính để tìm Thư) | H24: Code độc quyền tại AFKMobi đã phát hết; 3 code dùng chung BEGINNOW, KHAITHE, VINHQUANGOB do nguồn ghi rõ, không rõ hạn sử dụng | I24: https://afkmobi.com/tong-hop-gift-code-game-chien-vi-vinh-quang-moi-nhat.html
A25: 22 | B25: Clash of Critters | C25: CÔNG TY CỔ PHẦN GAMOTA | D25: https://www.facebook.com/nph.gamota | E25: =COUNTA('Tất cả code'!$C$178:$C$183) -> 6 | F25: Có code | G25: Trong game: mở menu Bạn bè (biểu tượng hai nhân vật ở góc dưới bên phải) > chọn Cài đặt (biểu tượng bánh răng ở phía trên) > cuộn xuống tìm mục Mã đổi thưởng (Redemption Code) > nhập code chính xác (phân biệt chữ hoa/thường) > nhấn Xác nhận. | H25: không rõ hạn — được nhiều nguồn liệt kê còn hoạt động trong tháng 10/2026; mã TATAMOON được một số nguồn báo hết hạn 24/10/2026 nên nên nhập sớm; mã openfestc ở một số nguồn khác ghi là openfestc26 — thử cả hai nếu cần | I25: https://dienthoaigiakho.vn/tin-cong-nghe/code-clash-of-critters/ https://www.pocketgamer.com/clash-of-critters/codes/
A26: 23 | B26: CMN Online | C26: NPH Chính thức | D26: https://www.facebook.com/p/v%c3%b4-c%e1%bb%b1c-ti%c3%aan-%c4%90%e1%bb%93-100090676061593 | E26: =0 -> 0 | F26: Không tìm thấy code | H26: Không tìm thấy code — CMN Online là tên NPH (nhà phát hành CMN Việt Nam), không phải tên một game cụ thể, nên không có danh sách giftcode riêng; các game của NPH này (Kiếm Vũ, Phong Vân Truyền Kỳ, Kiếm Thánh 2...) có code riêng từng game | I26: https://tripi.vn/blog/vi/game-app/ma-giftcode-cuu-thien-mobile-tripi https://afkmobi.com/giftcode/page/50 https://thethao247.vn/400-code-kiem-thanh-2-moi-nhat-va-cach-nhap-d270419.html
A27: 24 | B27: CookieRun: Kingdom | C27: Nhà Phát Hành Quốc Tế | D27: https://www.facebook.com/cookierunkingdom | E27: =COUNTA('Tất cả code'!$C$184:$C$184) -> 1 | F27: Có code | G27: Trong game nhấn biểu tượng menu 3 gạch ngang (góc trên bên phải) > Settings > tab Info > sao chép ID người chơi (User Info), sau đó truy cập trang nhập code chính thức của DevPlay (coupon.devplay.com/coupon/ck/en), dán ID và nhập code rồi nhấn Claim Reward. Khởi động lại game, nhận quà trong Thư (biểu tượng phong bì). | H27: Còn hạn: MISSEARTHBREAD26 (1500 Crystals, 500 Rainbow Cubes, 500 Choco Chalks), theo Pocket Gamer cập nhật 18/10/2026. Các code khác đã hết hạn nên không liệt kê. | I27: https://www.pocketgamer.com/cookie-run-kingdom/codes/ https://techysnoop.com/working-cookie-run-kingdom-codes/
A28: 25 | B28: Cơ Giáp Vô Hạn – Gamota | C28: CÔNG TY CỔ PHẦN GAMOTA | D28: https://www.facebook.com/ahxd.gamota https://www.facebook.com/nph.gamota https://www.facebook.com/tieungaogamota | E28: =COUNTA('Tất cả code'!$C$185:$C$196) -> 12 | F28: Có code | G28: Trong game bấm vào Avatar ở góc trên bên trái màn hình, mở nút Mã Quà Tặng, nhập mã rồi bấm Trao Đổi; quà sẽ được gửi về Thư ingame nếu nhập đúng. | H28: không rõ hạn - danh sách code dùng chung do afkmobi.com đăng ngày 09/05/2026 (cập nhật 12/05/2026), không ghi rõ hạn dùng nên có thể một số code đã hết hạn; code độc quyền của AFKMobi đã phát hết | I28: https://afkmobi.com/tong-hop-gift-code-game-co-giap-vo-han-gamota-moi-nhat.html https://afkmobi.com/giftcode/page/5
A29: 26 | B29: Cờ Tướng ZingPlay | C29: Công ty TNHH ZingPlay Việt Nam (Thuộc VNG) | D29: https://www.facebook.com/zingplayconggame | E29: =0 -> 0 | F29: Không tìm thấy code | G29: Các game trên nền tảng ZingPlay thường nhập code qua mục Giftcode/Nhập mã quà tặng trong game hoặc ứng dụng ZingPlay; mã chỉ dùng được một lần mỗi tài khoản và có thời hạn. | H29: Không tìm thấy code. Đã tìm qua nhiều truy vấn; các kết quả chỉ nói về game khác hoặc trang spam tự tạo mã ngẫu nhiên. Một nguồn đề cập ZINGPLAY25OFF cho Cờ Tướng Online nhưng mập mờ, không rõ áp dụng cho Cờ Tướng ZingPlay nên không liệt kê. | I29: https://xaydungso.vn/blog5/zingplay-code-vi-cb.html https://tripi.vn/blog/vi/game-app/huong-dan-nhan-code-chien-tuong-zingplay-tripi
A30: 27 | B30: Cờ Tỷ Phú ZingPlay | C30: Công ty TNHH ZingPlay Việt Nam (Thuộc VNG) | D30: https://www.facebook.com/zingplayconggame | E30: =0 -> 0 | F30: Không tìm thấy code | G30: Mở game Cờ Tỷ Phú ZingPlay và đăng nhập tài khoản, nhấn biểu tượng Cài Đặt (bánh răng) trên màn hình chính, chọn mục "Nhập Mã Code" hoặc "Nhập Quà Tặng", nhập chính xác mã code rồi nhấn "Xác nhận"/"Đồng Ý"; sau khi nhập thành công, vào Hòm Thư trong game để nhận phần thưởng. | H30: Không tìm thấy code. Trang xaydungso.vn chỉ đưa ví dụ mã code chứ không xác nhận code thật đang hoạt động; các trang linegames.org liệt kê chuỗi mã ngẫu nhiên là nội dung spam tự động, không phải code chính thức của ZingPlay/VNG. | I30: https://xaydungso.vn/blog5/co-ty-phu-zingplay-code-vi-cb.html https://www.linegames.org/en/C%E1%BB%9D-T%E1%BB%B7-Ph%C3%BA-2-ZingPlay-codes/337427056224/
A31: 28 | B31: Cửu Âm Chân Kinh 2 | C31: Công ty Cổ phần Trực tuyến GOSU | D31: https://www.facebook.com/cuuam.gosu.vn | E31: =0 -> 0 | F31: Không tìm thấy code | G31: Game phát giftcode riêng cho từng người chơi qua sự kiện, fanpage, diễn đàn và các trang tin game (như 2game.vn); nhập code trong game hoặc qua kênh đổi code chính thức của game theo hướng dẫn sự kiện | H31: Không tìm thấy code | I31: https://2game.vn/tag/giftcode-cuu-am-chan-kinh https://cuuam.gosu.vn/home/news/huong-dan/tips-ngay-dau-lam-tan-thu.html
A32: 29 | B32: Cửu Âm Chân Kinh Mobile | C32: Công ty Cổ phần Trực tuyến GOSU | D32: https://www.facebook.com/cuuamchankinhmobilegosu | E32: =COUNTA('Tất cả code'!$C$197:$C$204) -> 8 | F32: Có code | G32: Trong game nhấn biểu tượng Phúc Lợi > chọn mục Mã Quà Tặng > nhập chính xác code và nhấn Đổi Thưởng > vào khu vực Thư trong game để mở thư nhận quà. | H32: không rõ hạn — các code thuộc đợt ra mắt 25/5/2021, nguồn cập nhật 12/7/2025 nhưng không ghi trạng thái còn hạn, nên chưa xác minh được code còn dùng được | I32: https://tripi.vn/blog/vi/game-app/kham-pha-bo-suu-tap-giftcode-cuu-am-chan-kinh-mobile-gosu-tripi https://afkmobi.com/game/cuu-am-chan-kinh-mobile-gosu
A33: 30 | B33: Cửu Long Chí Tôn | C33: Công ty TNHH Dzogame | D33: https://www.facebook.com/cuulongchiton.dzogame | E33: =COUNTA('Tất cả code'!$C$205:$C$205) -> 1 | F33: Có code | G33: Đăng nhập vào game, chọn Kỳ Trân Các > chọn Giftcode > nhập code và ấn Nhận thưởng; sau đó quay lại giao diện chính, vào Kỳ Trân Tiêu Cục > chọn quà và nhấn Nhận. | H33: Chưa xác minh - code duy nhất nguồn ghi rõ là 9DVUONGGIA, lấy từ bài viết taimienphi.vn đăng tháng 6/2024 (cập nhật 7/2024), rất có thể đã hết hạn; không tìm thấy thêm code mới nào từ nguồn uy tín | I33: https://thuthuat.taimienphi.vn/code-cuu-long-chi-ton-77808n.aspx https://LAG.vn/cuu-long-chi-ton-9d-u.tag
A34: 31 | B34: Dancing Road: Color Ball Run! | C34: Amanotes | D34: https://www.facebook.com/magictiles3 | E34: =0 -> 0 | F34: Không tìm thấy code | H34: Không tìm thấy code - chỉ có các trang spam mã ngẫu nhiên (linegames.org), không có code chính thức nào được ghi nhận | I34: https://linegames.org
A35: 32 | B35: Dead Target | C35: VNG | D35: https://www.facebook.com/deadtarget | E35: =COUNTA('Tất cả code'!$C$206:$C$210) -> 5 | F35: Có code | G35: Trong game: Settings > Redeem Option > nhập code | H35: Các code trên đều ĐÃ HẾT HẠN (bài đăng 21/8/2025, hết hạn trong 8/2025); không tìm thấy code mới còn hạn | I35: https://deliventura.com/dead-target-codes/
A36: 33 | B36: Delta Force | C36: Garena | D36: https://www.facebook.com/deltaforcegamevn https://www.facebook.com/garenadeltaforcevn | E36: =COUNTA('Tất cả code'!$C$211:$C$221) -> 11 | F36: Có code | G36: Trong game: Sự kiện > Khác > Trung tâm đổi quà; hoặc nhập trên website redeem.df.garena.sg | H36: Code mới nhất cập nhật 09/10/2026; WELCOMETODF có hạn đến 25/10/2026; các code còn lại được nguồn ghi nhận còn nhập được | I36: https://fptshop.com.vn/tin-tuc/danh-gia/code-delta-force-209456
A37: 34 | B37: Dị Giới Sinh Tồn OEG | C37: Alo Game | D37: https://www.facebook.com/digioisinhtonoeg | E37: =0 -> 0 | F37: Không tìm thấy code | H37: Chưa xác minh - afkmobi có bài tổng hợp gift code (NPH Alo Game tặng đọc giả) nhưng không lấy được danh sách code cụ thể | I37: https://afkmobi.com
A38: 35 | B38: Diệt Quỷ Origin | C38: CÔNG TY TNHH TRUYỀN THÔNG HNXSOFT | D38: https://www.facebook.com/dietquyhnx | E38: =0 -> 0 | F38: Không tìm thấy code | H38: Chưa xác minh - download.com.vn và thegioigameviet đều có bài tổng hợp code nhưng không lấy được danh sách code cụ thể | I38: https://www.thegioigameviet.com https://download.com.vn
A39: 36 | B39: Doomsday: Last Survivors | C39: Gamota | D39: https://www.facebook.com/nph.gamota | E39: =COUNTA('Tất cả code'!$C$222:$C$229) -> 8 | F39: Có code | G39: Bấm avatar góc trên bên trái → Settings → Gift Code → nhập code → quà về hòm thư ingame | H39: Các code được các nguồn quốc tế cập nhật 10/2026 ghi nhận còn hoạt động; một số nguồn ghi nhận khác nhau về tình trạng hết hạn (DLSFAIRYTAIL có nguồn ghi đã hết hạn) | I39: https://www.pocketgamer.com/doomsday-last-survivors/codes/ https://cofregamers.com/en/doomsday-last-survivors-redeem-code-list/ https://buffbuff.com/blog/doomsday-last-survivors-codes
A40: 37 | B40: Duet Cats: Cute Cat Music | C40: Amanotes | D40: https://www.facebook.com/amanotes.duettiles | E40: =0 -> 0 | F40: Không tìm thấy code | H40: Không tìm thấy code - chỉ có các trang spam mã ngẫu nhiên (linegames.org), không có hệ thống giftcode chính thức được ghi nhận | I40: https://www.linegames.org
...

Sheet Tất cả code
A1: TẤT CẢ GIFTCODE — 340 GAME (MỖI DÒNG 1 MÃ)
A2: Ô màu vàng ở cột 'Đã nhập?' là ô bạn tự điền: gõ 'x' khi đã nhập mã đó. Cách nhập và ghi chú của từng game xem ở sheet 'Tổng hợp 340 game'.
A3: STT | B3: Tên game | C3: Giftcode | D3: Nhà phát hành | E3: Đã nhập?
A4: 1 | B4: 3Q Đào Đào Đào | C4: 3QDAODAO | D4: CÔNG TY TNHH JOYGAMES
A5: 2 | B5: 3Q Đào Đào Đào | C5: 3QVIP666 | D5: CÔNG TY TNHH JOYGAMES
A6: 3 | B6: 3Q Đào Đào Đào | C6: DAOBAO2026 | D6: CÔNG TY TNHH JOYGAMES
A7: 4 | B7: 3Q Đào Đào Đào | C7: DAODAODAO999 | D7: CÔNG TY TNHH JOYGAMES
A8: 5 | B8: 3Q Đào Đào Đào | C8: GACHA1024 | D8: CÔNG TY TNHH JOYGAMES
A9: 6 | B9: 3Q Đào Đào Đào | C9: TIEUKIEUVIP | D9: CÔNG TY TNHH JOYGAMES
A10: 7 | B10: 3Q Đào Đào Đào | C10: 3QDAODAODTN | D10: CÔNG TY TNHH JOYGAMES
A11: 8 | B11: 3Q Đào Đào Đào | C11: HUYNHPHUONGFAPTV | D11: CÔNG TY TNHH JOYGAMES
A12: 9 | B12: Au 2! | C12: HAPPYVALENTINE | D12: VTC (VTC Intecom & VTC Mobile)
A13: 10 | B13: Au 2! | C13: QUYMAO2023 | D13: VTC (VTC Intecom & VTC Mobile)
A14: 11 | B14: Au 2! | C14: DENBUBAOTRI1202 | D14: VTC (VTC Intecom & VTC Mobile)
A15: 12 | B15: Au 2! | C15: DOUBLEGIFT | D15: VTC (VTC Intecom & VTC Mobile)
... A1891: 1888 | B1891: ZingSpeed Mobile | C1891: SKINT3MAR | D1891: CÔNG TY CỔ PHẦN TẬP ĐOÀN VNG
B1893: Tổng số code: | C1893: =COUNTA(C4:C1891) -> 1888
B1894: Đã nhập: | C1894: =COUNTIF(E4:E1891,"x")+COUNTIF(E4:E1891,"X") -> 0
B1895: Chưa nhập: | C1895: =C1893-C1894 -> 1888
